Traceback (most recent call last):
  File "C:\Users\BINH\AppData\Local\Programs\Python\Python311\Lib\site-packages\pandas\core\indexes\base.py", line 3802, in get_loc
    return self._engine.get_loc(casted_key)
           ^^^^^^^^^^^^^^^^^^^^^^^^^^^^^^^^
  File "pandas\_libs\index.pyx", line 138, in pandas._libs.index.IndexEngine.get_loc
  File "pandas\_libs\index.pyx", line 165, in pandas._libs.index.IndexEngine.get_loc
  File "pandas\_libs\hashtable_class_helper.pxi", line 5745, in pandas._libs.hashtable.PyObjectHashTable.get_item
  File "pandas\_libs\hashtable_class_helper.pxi", line 5753, in pandas._libs.hashtable.PyObjectHashTable.get_item
KeyError: 'label'

The above exception was the direct cause of the following exception:

Traceback (most recent call last):
  File "D:\hate speech\src\train.py", line 34, in <module>
    dataset = load_and_prepare_datasets()
              ^^^^^^^^^^^^^^^^^^^^^^^^^^^
  File "D:\hate speech\src\dataset.py", line 20, in load_and_prepare_datasets
    test_df["label"] = test_df["label"].map(label_mapping)
                       ~~~~~~~^^^^^^^^^
  File "C:\Users\BINH\AppData\Local\Programs\Python\Python311\Lib\site-packages\pandas\core\frame.py", line 3807, in __getitem__
    indexer = self.columns.get_loc(key)
              ^^^^^^^^^^^^^^^^^^^^^^^^^
  File "C:\Users\BINH\AppData\Local\Programs\Python\Python311\Lib\site-packages\pandas\core\indexes\base.py", line 3804, in get_loc
    raise KeyError(key) from err
KeyError: 'label'
